Workbook

Sheet Dashboard
A1: Mindset Shift Stack Tracker
A2: =TEXT(TODAY(),"dddd, mmmm d, yyyy") · Keep the momentum going.
A5: TOTAL XP ⚡ | G5: CURRENT LEVEL | L5: DONE TODAY ✅ | Q5: TODAY'S RATE
A6: ='XP & Levels'!C13 | G6: ='XP & Levels'!D11 | L6: =COUNTIF('Check-In'!Q5:Q16,"✅") | Q6: =IFERROR(COUNTIF('Check-In'!Q5:Q16,"✅")/COUNTA('Habits Setup'!B5:B16),0)
A11: Your Avatar
A12: =IF('XP & Levels'!C13>=3001,"👑",IF('XP & Levels'!C13>=1751,"💎",IF('XP & Levels'!C13>=1001,"⚡",IF('XP & Levels'!C13>=601,"🔥",IF('XP & Levels'!C13>=301,"🌳",IF('XP & Levels'!C13>=101,"🌿","🌱"))))))
A16: ='XP & Levels'!D11
A17: ='XP & Levels'!C13&" XP · Next: "&'XP & Levels'!E14&" XP"
A18: =IF('XP & Levels'!C13>='XP & Levels'!E14,"▓▓▓▓▓▓▓▓▓▓▓▓▓▓▓▓▓▓▓▓ MAX",REPT("▓",ROUND(MIN('XP & Levels'!C13/'XP & Levels'!E14,1)*20,0))&REPT("░",20-ROUND(MIN('XP & Levels'!C13/'XP & Levels'!E14,1)*20,0))&" "&TEXT(MIN('XP & Levels'!C13/'XP & Levels'!E14,1),"0%"))
A20: Today's Habits
A21: HABIT | B21: CATEGORY | C21: XP | D21: STATUS | E21: STREAK | F21: PROGRESS BAR
A22: 💧 Drink 8 Glasses of Water | B22: ='Habits Setup'!C9 | C22: ='Habits Setup'!E9 | D22: ='Check-In'!Q9 | E22: ='Check-In'!C9 | F22: =REPT("█",ROUND(=IFERROR('Check-In'!C9/14,0)*20,0))&REPT("░",20-ROUND(=IFERROR('Check-In'!C9/14,0)*20,0))&" "&TEXT(=IFERROR('Check-In'!C9/14,0),"0%")
A23: 🏋️ 30-Min Workout | B23: ='Habits Setup'!C10 | C23: ='Habits Setup'!E10 | D23: ='Check-In'!Q10 | E23: ='Check-In'!C10 | F23: =REPT("█",ROUND(=IFERROR('Check-In'!C10/14,0)*20,0))&REPT("░",20-ROUND(=IFERROR('Check-In'!C10/14,0)*20,0))&" "&TEXT(=IFERROR('Check-In'!C10/14,0),"0%")
A24: 🧘 Meditate 10 Min | B24: ='Habits Setup'!C11 | C24: ='Habits Setup'!E11 | D24: ='Check-In'!Q11 | E24: ='Check-In'!C11 | F24: =REPT("█",ROUND(=IFERROR('Check-In'!C11/14,0)*20,0))&REPT("░",20-ROUND(=IFERROR('Check-In'!C11/14,0)*20,0))&" "&TEXT(=IFERROR('Check-In'!C11/14,0),"0%")
A25: 📚 Read 30 Minutes | B25: ='Habits Setup'!C12 | C25: ='Habits Setup'!E12 | D25: ='Check-In'!Q12 | E25: ='Check-In'!C12 | F25: =REPT("█",ROUND(=IFERROR('Check-In'!C12/14,0)*20,0))&REPT("░",20-ROUND(=IFERROR('Check-In'!C12/14,0)*20,0))&" "&TEXT(=IFERROR('Check-In'!C12/14,0),"0%")
A26: 🚫 No Social Media 1hr AM | B26: ='Habits Setup'!C13 | C26: ='Habits Setup'!E13 | D26: ='Check-In'!Q13 | E26: ='Check-In'!C13 | F26: =REPT("█",ROUND(=IFERROR('Check-In'!C13/14,0)*20,0))&REPT("░",20-ROUND(=IFERROR('Check-In'!C13/14,0)*20,0))&" "&TEXT(=IFERROR('Check-In'!C13/14,0),"0%")
A27: 🙏 Gratitude Journal | B27: ='Habits Setup'!C14 | C27: ='Habits Setup'!E14 | D27: ='Check-In'!Q14 | E27: ='Check-In'!C14 | F27: =REPT("█",ROUND(=IFERROR('Check-In'!C14/14,0)*20,0))&REPT("░",20-ROUND(=IFERROR('Check-In'!C14/14,0)*20,0))&" "&TEXT(=IFERROR('Check-In'!C14/14,0),"0%")
A28: 👟 10,000 Steps | B28: ='Habits Setup'!C15 | C28: ='Habits Setup'!E15 | D28: ='Check-In'!Q15 | E28: ='Check-In'!C15 | F28: =REPT("█",ROUND(=IFERROR('Check-In'!C15/14,0)*20,0))&REPT("░",20-ROUND(=IFERROR('Check-In'!C15/14,0)*20,0))&" "&TEXT(=IFERROR('Check-In'!C15/14,0),"0%")
A29: 😴 Sleep by 11pm | B29: ='Habits Setup'!C16 | C29: ='Habits Setup'!E16 | D29: ='Check-In'!Q16 | E29: ='Check-In'!C16 | F29: =REPT("█",ROUND(=IFERROR('Check-In'!C16/14,0)*20,0))&REPT("░",20-ROUND(=IFERROR('Check-In'!C16/14,0)*20,0))&" "&TEXT(=IFERROR('Check-In'!C16/14,0),"0%")
A30: 💼 Deep Work 2 Hours | B30: ='Habits Setup'!C17 | C30: ='Habits Setup'!E17 | D30: ='Check-In'!Q17 | E30: ='Check-In'!C17 | F30: =REPT("█",ROUND(=IFERROR('Check-In'!C17/14,0)*20,0))&REPT("░",20-ROUND(=IFERROR('Check-In'!C17/14,0)*20,0))&" "&TEXT(=IFERROR('Check-In'!C17/14,0),"0%")
A31: 📞 Connect with Someone | B31: ='Habits Setup'!C18 | C31: ='Habits Setup'!E18 | D31: ='Check-In'!Q18 | E31: ='Check-In'!C18 | F31: =REPT("█",ROUND(=IFERROR('Check-In'!C18/14,0)*20,0))&REPT("░",20-ROUND(=IFERROR('Check-In'!C18/14,0)*20,0))&" "&TEXT(=IFERROR('Check-In'!C18/14,0),"0%")
A32: 🥗 Eat Clean All Day | B32: ='Habits Setup'!C19 | C32: ='Habits Setup'!E19 | D32: ='Check-In'!Q19 | E32: ='Check-In'!C19 | F32: =REPT("█",ROUND(=IFERROR('Check-In'!C19/14,0)*20,0))&REPT("░",20-ROUND(=IFERROR('Check-In'!C19/14,0)*20,0))&" "&TEXT(=IFERROR('Check-In'!C19/14,0),"0%")
A33: ✍️ Write / Journal | B33: ='Habits Setup'!C20 | C33: ='Habits Setup'!E20 | D33: ='Check-In'!Q20 | E33: ='Check-In'!C20 | F33: =REPT("█",ROUND(=IFERROR('Check-In'!C20/14,0)*20,0))&REPT("░",20-ROUND(=IFERROR('Check-In'!C20/14,0)*20,0))&" "&TEXT(=IFERROR('Check-In'!C20/14,0),"0%")
A35: "Momentum, not motivation. Every rep compounds."

Sheet Habits Setup
A1: ⚙ Habits Setup
A2: Add, remove or customise your habits. XP per completion drives your level.
A4: # | B4: Habit Name | C4: Category | D4: Frequency | E4: XP Value | F4: Target/Wk | G4: Icon | H4: Active? | I4: Color | J4: Notes
A5: 1 | B5: Drink 8 Glasses of Water | C5: Health | D5: Daily | E5: 10 | F5: 7 | G5: 💧 | H5: Yes | I5: 0EA5E9
A6: 2 | B6: 30-Min Workout | C6: Fitness | D6: Daily | E6: 25 | F6: 7 | G6: 🏋️ | H6: Yes | I6: 10B981
A7: 3 | B7: Meditate 10 Min | C7: Mindset | D7: Daily | E7: 20 | F7: 7 | G7: 🧘 | H7: Yes | I7: 8B5CF6
A8: 4 | B8: Read 30 Minutes | C8: Focus | D8: Daily | E8: 20 | F8: 7 | G8: 📚 | H8: Yes | I8: F59E0B
A9: 5 | B9: No Social Media 1hr AM | C9: Mindset | D9: Daily | E9: 15 | F9: 7 | G9: 🚫 | H9: Yes | I9: 8B5CF6
A10: 6 | B10: Gratitude Journal | C10: Mindset | D10: Daily | E10: 15 | F10: 7 | G10: 🙏 | H10: Yes | I10: 8B5CF6
A11: 7 | B11: 10,000 Steps | C11: Fitness | D11: Daily | E11: 20 | F11: 7 | G11: 👟 | H11: Yes | I11: 10B981
A12: 8 | B12: Sleep by 11pm | C12: Health | D12: Daily | E12: 15 | F12: 7 | G12: 😴 | H12: Yes | I12: 0EA5E9
A13: 9 | B13: Deep Work 2 Hours | C13: Business | D13: Daily | E13: 30 | F13: 7 | G13: 💼 | H13: Yes | I13: EF4444
A14: 10 | B14: Connect with Someone | C14: Social | D14: Weekly | E14: 20 | F14: 1 | G14: 📞 | H14: Yes | I14: EC4899
A15: 11 | B15: Eat Clean All Day | C15: Health | D15: Daily | E15: 15 | F15: 7 | G15: 🥗 | H15: Yes | I15: 0EA5E9
A16: 12 | B16: Write / Journal | C16: Focus | D16: Daily | E16: 15 | F16: 7 | G16: ✍️ | H16: Yes | I16: F59E0B
A18: 💡 XP Values guide: Low effort = 10 XP · Medium = 15–20 XP · Hard = 25–30 XP · Elite = 40+ XP

Sheet Check-In
A1: ✅ Daily Check-In
A2: Mark each habit daily. XP earns automatically. Momentum never resets.
A4: HABIT | B4: ⚡ XP/Habit | C4: 🔥 Streak | D4: Tue 10 Mar | E4: Wed 11 Mar | F4: Thu 12 Mar | G4: Fri 13 Mar | H4: Sat 14 Mar | I4: Sun 15 Mar | J4: Mon 16 Mar | K4: Tue 17 Mar | L4: Wed 18 Mar | M4: Thu 19 Mar | N4: Fri 20 Mar | O4: Sat 21 Mar | P4: Sun 22 Mar | Q4: Mon 23 Mar
A5: 💧 Drink 8 Glasses of Water | B5: ='Habits Setup'!E5 | C5: =COUNTIF(D5:Q5,"✅") | D5: — | E5: — | F5: — | G5: — | H5: — | I5: — | J5: — | K5: — | L5: — | M5: — | N5: — | O5: — | P5: — | Q5: —
A6: 🏋️ 30-Min Workout | B6: ='Habits Setup'!E6 | C6: =COUNTIF(D6:Q6,"✅") | D6: — | E6: — | F6: — | G6: — | H6: — | I6: — | J6: — | K6: — | L6: — | M6: — | N6: — | O6: — | P6: — | Q6: —
A7: 🧘 Meditate 10 Min | B7: ='Habits Setup'!E7 | C7: =COUNTIF(D7:Q7,"✅") | D7: — | E7: — | F7: — | G7: — | H7: — | I7: — | J7: — | K7: — | L7: — | M7: — | N7: — | O7: — | P7: — | Q7: —
A8: 📚 Read 30 Minutes | B8: ='Habits Setup'!E8 | C8: =COUNTIF(D8:Q8,"✅") | D8: — | E8: — | F8: — | G8: — | H8: — | I8: — | J8: — | K8: — | L8: — | M8: — | N8: — | O8: — | P8: — | Q8: —
A9: 🚫 No Social Media 1hr AM | B9: ='Habits Setup'!E9 | C9: =COUNTIF(D9:Q9,"✅") | D9: — | E9: — | F9: — | G9: — | H9: — | I9: — | J9: — | K9: — | L9: — | M9: — | N9: — | O9: — | P9: — | Q9: —
A10: 🙏 Gratitude Journal | B10: ='Habits Setup'!E10 | C10: =COUNTIF(D10:Q10,"✅") | D10: — | E10: — | F10: — | G10: — | H10: — | I10: — | J10: — | K10: — | L10: — | M10: — | N10: — | O10: — | P10: — | Q10: —
A11: 👟 10,000 Steps | B11: ='Habits Setup'!E11 | C11: =COUNTIF(D11:Q11,"✅") | D11: — | E11: — | F11: — | G11: — | H11: — | I11: — | J11: — | K11: — | L11: — | M11: — | N11: — | O11: — | P11: — | Q11: —
A12: 😴 Sleep by 11pm | B12: ='Habits Setup'!E12 | C12: =COUNTIF(D12:Q12,"✅") | D12: — | E12: — | F12: — | G12: — | H12: — | I12: — | J12: — | K12: — | L12: — | M12: — | N12: — | O12: — | P12: — | Q12: —
A13: 💼 Deep Work 2 Hours | B13: ='Habits Setup'!E13 | C13: =COUNTIF(D13:Q13,"✅") | D13: — | E13: — | F13: — | G13: — | H13: — | I13: — | J13: — | K13: — | L13: — | M13: — | N13: — | O13: — | P13: — | Q13: —
A14: 📞 Connect with Someone | B14: ='Habits Setup'!E14 | C14: =COUNTIF(D14:Q14,"✅") | D14: — | E14: — | F14: — | G14: — | H14: — | I14: — | J14: — | K14: — | L14: — | M14: — | N14: — | O14: — | P14: — | Q14: —
A15: 🥗 Eat Clean All Day | B15: ='Habits Setup'!E15 | C15: =COUNTIF(D15:Q15,"✅") | D15: — | E15: — | F15: — | G15: — | H15: — | I15: — | J15: — | K15: — | L15: — | M15: — | N15: — | O15: — | P15: — | Q15: —
A16: ✍️ Write / Journal | B16: ='Habits Setup'!E16 | C16: =COUNTIF(D16:Q16,"✅") | D16: — | E16: — | F16: — | G16: — | H16: — | I16: — | J16: — | K16: — | L16: — | M16: — | N16: — | O16: — | P16: — | Q16: —
A17: ⚡ XP EARNED TODAY | D17: =IF(D5="✅",'Habits Setup'!E5,0)+IF(D6="✅",'Habits Setup'!E6,0)+IF(D7="✅",'Habits Setup'!E7,0)+IF(D8="✅",'Habits Setup'!E8,0)+IF(D9="✅",'Habits Setup'!E9,0)+IF(D10="✅",'Habits Setup'!E10,0)+IF(D11="✅",'Habits Setup'!E11,0)+IF(D12="✅",'Habits Setup'!E12,0)+IF(D13="✅",'Habits Setup'!E13,0)+IF(D14="✅",'Habits Setup'!E14,0)+IF(D15="✅",'Habits Setup'!E15,0)+IF(D16="✅",'Habits Setup'!E16,0) | E17: =IF(E5="✅",'Habits Setup'!E5,0)+IF(E6="✅",'Habits Setup'!E6,0)+IF(E7="✅",'Habits Setup'!E7,0)+IF(E8="✅",'Habits Setup'!E8,0)+IF(E9="✅",'Habits Setup'!E9,0)+IF(E10="✅",'Habits Setup'!E10,0)+IF(E11="✅",'Habits Setup'!E11,0)+IF(E12="✅",'Habits Setup'!E12,0)+IF(E13="✅",'Habits Setup'!E13,0)+IF(E14="✅",'Habits Setup'!E14,0)+IF(E15="✅",'Habits Setup'!E15,0)+IF(E16="✅",'Habits Setup'!E16,0) | F17: =IF(F5="✅",'Habits Setup'!E5,0)+IF(F6="✅",'Habits Setup'!E6,0)+IF(F7="✅",'Habits Setup'!E7,0)+IF(F8="✅",'Habits Setup'!E8,0)+IF(F9="✅",'Habits Setup'!E9,0)+IF(F10="✅",'Habits Setup'!E10,0)+IF(F11="✅",'Habits Setup'!E11,0)+IF(F12="✅",'Habits Setup'!E12,0)+IF(F13="✅",'Habits Setup'!E13,0)+IF(F14="✅",'Habits Setup'!E14,0)+IF(F15="✅",'Habits Setup'!E15,0)+IF(F16="✅",'Habits Setup'!E16,0) | G17: =IF(G5="✅",'Habits Setup'!E5,0)+IF(G6="✅",'Habits Setup'!E6,0)+IF(G7="✅",'Habits Setup'!E7,0)+IF(G8="✅",'Habits Setup'!E8,0)+IF(G9="✅",'Habits Setup'!E9,0)+IF(G10="✅",'Habits Setup'!E10,0)+IF(G11="✅",'Habits Setup'!E11,0)+IF(G12="✅",'Habits Setup'!E12,0)+IF(G13="✅",'Habits Setup'!E13,0)+IF(G14="✅",'Habits Setup'!E14,0)+IF(G15="✅",'Habits Setup'!E15,0)+IF(G16="✅",'Habits Setup'!E16,0) | H17: =IF(H5="✅",'Habits Setup'!E5,0)+IF(H6="✅",'Habits Setup'!E6,0)+IF(H7="✅",'Habits Setup'!E7,0)+IF(H8="✅",'Habits Setup'!E8,0)+IF(H9="✅",'Habits Setup'!E9,0)+IF(H10="✅",'Habits Setup'!E10,0)+IF(H11="✅",'Habits Setup'!E11,0)+IF(H12="✅",'Habits Setup'!E12,0)+IF(H13="✅",'Habits Setup'!E13,0)+IF(H14="✅",'Habits Setup'!E14,0)+IF(H15="✅",'Habits Setup'!E15,0)+IF(H16="✅",'Habits Setup'!E16,0) | I17: =IF(I5="✅",'Habits Setup'!E5,0)+IF(I6="✅",'Habits Setup'!E6,0)+IF(I7="✅",'Habits Setup'!E7,0)+IF(I8="✅",'Habits Setup'!E8,0)+IF(I9="✅",'Habits Setup'!E9,0)+IF(I10="✅",'Habits Setup'!E10,0)+IF(I11="✅",'Habits Setup'!E11,0)+IF(I12="✅",'Habits Setup'!E12,0)+IF(I13="✅",'Habits Setup'!E13,0)+IF(I14="✅",'Habits Setup'!E14,0)+IF(I15="✅",'Habits Setup'!E15,0)+IF(I16="✅",'Habits Setup'!E16,0) | J17: =IF(J5="✅",'Habits Setup'!E5,0)+IF(J6="✅",'Habits Setup'!E6,0)+IF(J7="✅",'Habits Setup'!E7,0)+IF(J8="✅",'Habits Setup'!E8,0)+IF(J9="✅",'Habits Setup'!E9,0)+IF(J10="✅",'Habits Setup'!E10,0)+IF(J11="✅",'Habits Setup'!E11,0)+IF(J12="✅",'Habits Setup'!E12,0)+IF(J13="✅",'Habits Setup'!E13,0)+IF(J14="✅",'Habits Setup'!E14,0)+IF(J15="✅",'Habits Setup'!E15,0)+IF(J16="✅",'Habits Setup'!E16,0) | K17: =IF(K5="✅",'Habits Setup'!E5,0)+IF(K6="✅",'Habits Setup'!E6,0)+IF(K7="✅",'Habits Setup'!E7,0)+IF(K8="✅",'Habits Setup'!E8,0)+IF(K9="✅",'Habits Setup'!E9,0)+IF(K10="✅",'Habits Setup'!E10,0)+IF(K11="✅",'Habits Setup'!E11,0)+IF(K12="✅",'Habits Setup'!E12,0)+IF(K13="✅",'Habits Setup'!E13,0)+IF(K14="✅",'Habits Setup'!E14,0)+IF(K15="✅",'Habits Setup'!E15,0)+IF(K16="✅",'Habits Setup'!E16,0) | L17: =IF(L5="✅",'Habits Setup'!E5,0)+IF(L6="✅",'Habits Setup'!E6,0)+IF(L7="✅",'Habits Setup'!E7,0)+IF(L8="✅",'Habits Setup'!E8,0)+IF(L9="✅",'Habits Setup'!E9,0)+IF(L10="✅",'Habits Setup'!E10,0)+IF(L11="✅",'Habits Setup'!E11,0)+IF(L12="✅",'Habits Setup'!E12,0)+IF(L13="✅",'Habits Setup'!E13,0)+IF(L14="✅",'Habits Setup'!E14,0)+IF(L15="✅",'Habits Setup'!E15,0)+IF(L16="✅",'Habits Setup'!E16,0) | M17: =IF(M5="✅",'Habits Setup'!E5,0)+IF(M6="✅",'Habits Setup'!E6,0)+IF(M7="✅",'Habits Setup'!E7,0)+IF(M8="✅",'Habits Setup'!E8,0)+IF(M9="✅",'Habits Setup'!E9,0)+IF(M10="✅",'Habits Setup'!E10,0)+IF(M11="✅",'Habits Setup'!E11,0)+IF(M12="✅",'Habits Setup'!E12,0)+IF(M13="✅",'Habits Setup'!E13,0)+IF(M14="✅",'Habits Setup'!E14,0)+IF(M15="✅",'Habits Setup'!E15,0)+IF(M16="✅",'Habits Setup'!E16,0) | N17: =IF(N5="✅",'Habits Setup'!E5,0)+IF(N6="✅",'Habits Setup'!E6,0)+IF(N7="✅",'Habits Setup'!E7,0)+IF(N8="✅",'Habits Setup'!E8,0)+IF(N9="✅",'Habits Setup'!E9,0)+IF(N10="✅",'Habits Setup'!E10,0)+IF(N11="✅",'Habits Setup'!E11,0)+IF(N12="✅",'Habits Setup'!E12,0)+IF(N13="✅",'Habits Setup'!E13,0)+IF(N14="✅",'Habits Setup'!E14,0)+IF(N15="✅",'Habits Setup'!E15,0)+IF(N16="✅",'Habits Setup'!E16,0) | O17: =IF(O5="✅",'Habits Setup'!E5,0)+IF(O6="✅",'Habits Setup'!E6,0)+IF(O7="✅",'Habits Setup'!E7,0)+IF(O8="✅",'Habits Setup'!E8,0)+IF(O9="✅",'Habits Setup'!E9,0)+IF(O10="✅",'Habits Setup'!E10,0)+IF(O11="✅",'Habits Setup'!E11,0)+IF(O12="✅",'Habits Setup'!E12,0)+IF(O13="✅",'Habits Setup'!E13,0)+IF(O14="✅",'Habits Setup'!E14,0)+IF(O15="✅",'Habits Setup'!E15,0)+IF(O16="✅",'Habits Setup'!E16,0) | P17: =IF(P5="✅",'Habits Setup'!E5,0)+IF(P6="✅",'Habits Setup'!E6,0)+IF(P7="✅",'Habits Setup'!E7,0)+IF(P8="✅",'Habits Setup'!E8,0)+IF(P9="✅",'Habits Setup'!E9,0)+IF(P10="✅",'Habits Setup'!E10,0)+IF(P11="✅",'Habits Setup'!E11,0)+IF(P12="✅",'Habits Setup'!E12,0)+IF(P13="✅",'Habits Setup'!E13,0)+IF(P14="✅",'Habits Setup'!E14,0)+IF(P15="✅",'Habits Setup'!E15,0)+IF(P16="✅",'Habits Setup'!E16,0) | Q17: =IF(Q5="✅",'Habits Setup'!E5,0)+IF(Q6="✅",'Habits Setup'!E6,0)+IF(Q7="✅",'Habits Setup'!E7,0)+IF(Q8="✅",'Habits Setup'!E8,0)+IF(Q9="✅",'Habits Setup'!E9,0)+IF(Q10="✅",'Habits Setup'!E10,0)+IF(Q11="✅",'Habits Setup'!E11,0)+IF(Q12="✅",'Habits Setup'!E12,0)+IF(Q13="✅",'Habits Setup'!E13,0)+IF(Q14="✅",'Habits Setup'!E14,0)+IF(Q15="✅",'Habits Setup'!E15,0)+IF(Q16="✅",'Habits Setup'!E16,0)

Sheet XP & Levels
A1: ⚡ XP & Levels
A2: Your momentum never resets. Every ✅ earns XP. Keep stacking.
A4: YOUR AVATAR | G4: Level Progression
A5: =IF(B8>=3001,"👑",IF(B8>=1751,"💎",IF(B8>=1001,"⚡",IF(B8>=601,"🔥",IF(B8>=301,"🌳",IF(B8>=101,"🌿","🌱")))))) | G5: Level | H5: Title | I5: XP Range | J5: Status
G6: 1 | H6: 🌱 Seed | I6: 0 – 100 | J6: =IF(AND(C13>=0,C13<=100),"◀ CURRENT","—")
G7: 2 | H7: 🌿 Sprout | I7: 101 – 300 | J7: =IF(AND(C13>=101,C13<=300),"◀ CURRENT","—")
G8: 3 | H8: 🌳 Sapling | I8: 301 – 600 | J8: =IF(AND(C13>=301,C13<=600),"◀ CURRENT","—")
G9: 4 | H9: 🔥 Achiever | I9: 601 – 1,000 | J9: =IF(AND(C13>=601,C13<=1000),"◀ CURRENT","—")
G10: 5 | H10: ⚡ Champion | I10: 1,001 – 1,750 | J10: =IF(AND(C13>=1001,C13<=1750),"◀ CURRENT","—")
A11: =IF(B8>=3001,"👑 ELITE",IF(B8>=1751,"💎 LEGEND",IF(B8>=1001,"⚡ CHAMPION",IF(B8>=601,"🔥 ACHIEVER",IF(B8>=301,"🌳 SAPLING",IF(B8>=101,"🌿 SPROUT","🌱 SEED")))))) | G11: 6 | H11: 💎 Legend | I11: 1,751 – 3,000 | J11: =IF(AND(C13>=1751,C13<=3000),"◀ CURRENT","—")
G12: 7 | H12: 👑 Elite | I12: 3,001+ | J12: =IF(AND(C13>=3001,C13<=9999),"◀ CURRENT","—")
A13: TOTAL XP | C13: =(COUNTIF('Check-In'!D5:Q5,"✅")*'Habits Setup'!E5)+(COUNTIF('Check-In'!D6:Q6,"✅")*'Habits Setup'!E6)+(COUNTIF('Check-In'!D7:Q7,"✅")*'Habits Setup'!E7)+(COUNTIF('Check-In'!D8:Q8,"✅")*'Habits Setup'!E8)+(COUNTIF('Check-In'!D9:Q9,"✅")*'Habits Setup'!E9)+(COUNTIF('Check-In'!D10:Q10,"✅")*'Habits Setup'!E10)+(COUNTIF('Check-In'!D11:Q11,"✅")*'Habits Setup'!E11)+(COUNTIF('Check-In'!D12:Q12,"✅")*'Habits Setup'!E12)+(COUNTIF('Check-In'!D13:Q13,"✅")*'Habits Setup'!E13)+(COUNTIF('Check-In'!D14:Q14,"✅")*'Habits Setup'!E14)+(COUNTIF('Check-In'!D15:Q15,"✅")*'Habits Setup'!E15)+(COUNTIF('Check-In'!D16:Q16,"✅")*'Habits Setup'!E16)
A14: NEXT LEVEL AT | C14: =IF(C13>=3001,"MAX LEVEL 👑",IF(C13>=1751,3001,IF(C13>=1001,1751,IF(C13>=601,1001,IF(C13>=301,601,IF(C13>=101,301,101))))))
A15: =IF(C13>=3001,"▓▓▓▓▓▓▓▓▓▓▓▓▓▓▓▓▓▓▓▓ MAX",LET(pct,MIN(C13/C14,1),REPT("▓",ROUND(pct*20,0))&REPT("░",20-ROUND(pct*20,0))&" "&TEXT(pct,"0%")))
A16: DAYS TRACKED | C16: =IF(COUNTIF('Check-In'!D5:Q5,"✅")>0,1,0)+IF(COUNTIF('Check-In'!D6:Q6,"✅")>0,1,0)+IF(COUNTIF('Check-In'!D7:Q7,"✅")>0,1,0)+IF(COUNTIF('Check-In'!D8:Q8,"✅")>0,1,0)+IF(COUNTIF('Check-In'!D9:Q9,"✅")>0,1,0)+IF(COUNTIF('Check-In'!D10:Q10,"✅")>0,1,0)+IF(COUNTIF('Check-In'!D11:Q11,"✅")>0,1,0)+IF(COUNTIF('Check-In'!D12:Q12,"✅")>0,1,0)+IF(COUNTIF('Check-In'!D13:Q13,"✅")>0,1,0)+IF(COUNTIF('Check-In'!D14:Q14,"✅")>0,1,0)+IF(COUNTIF('Check-In'!D15:Q15,"✅")>0,1,0)+IF(COUNTIF('Check-In'!D16:Q16,"✅")>0,1,0)
A17: "Momentum, not motivation."
A20: XP Breakdown by Habit
A21: Habit | B21: XP/Rep | C21: ✅ Count | D21: Total XP | E21: % of Total
A22: 💧 Drink 8 Glasses of Water | B22: ='Habits Setup'!E5 | C22: =COUNTIF('Check-In'!D5:Q5,"✅") | D22: =B22*C22 | E22: =IFERROR(D22/C13,0)
A23: 🏋️ 30-Min Workout | B23: ='Habits Setup'!E6 | C23: =COUNTIF('Check-In'!D6:Q6,"✅") | D23: =B23*C23 | E23: =IFERROR(D23/C13,0)
A24: 🧘 Meditate 10 Min | B24: ='Habits Setup'!E7 | C24: =COUNTIF('Check-In'!D7:Q7,"✅") | D24: =B24*C24 | E24: =IFERROR(D24/C13,0)
A25: 📚 Read 30 Minutes | B25: ='Habits Setup'!E8 | C25: =COUNTIF('Check-In'!D8:Q8,"✅") | D25: =B25*C25 | E25: =IFERROR(D25/C13,0)
A26: 🚫 No Social Media 1hr AM | B26: ='Habits Setup'!E9 | C26: =COUNTIF('Check-In'!D9:Q9,"✅") | D26: =B26*C26 | E26: =IFERROR(D26/C13,0)
A27: 🙏 Gratitude Journal | B27: ='Habits Setup'!E10 | C27: =COUNTIF('Check-In'!D10:Q10,"✅") | D27: =B27*C27 | E27: =IFERROR(D27/C13,0)
A28: 👟 10,000 Steps | B28: ='Habits Setup'!E11 | C28: =COUNTIF('Check-In'!D11:Q11,"✅") | D28: =B28*C28 | E28: =IFERROR(D28/C13,0)
A29: 😴 Sleep by 11pm | B29: ='Habits Setup'!E12 | C29: =COUNTIF('Check-In'!D12:Q12,"✅") | D29: =B29*C29 | E29: =IFERROR(D29/C13,0)
A30: 💼 Deep Work 2 Hours | B30: ='Habits Setup'!E13 | C30: =COUNTIF('Check-In'!D13:Q13,"✅") | D30: =B30*C30 | E30: =IFERROR(D30/C13,0)
A31: 📞 Connect with Someone | B31: ='Habits Setup'!E14 | C31: =COUNTIF('Check-In'!D14:Q14,"✅") | D31: =B31*C31 | E31: =IFERROR(D31/C13,0)
A32: 🥗 Eat Clean All Day | B32: ='Habits Setup'!E15 | C32: =COUNTIF('Check-In'!D15:Q15,"✅") | D32: =B32*C32 | E32: =IFERROR(D32/C13,0)
A33: ✍️ Write / Journal | B33: ='Habits Setup'!E16 | C33: =COUNTIF('Check-In'!D16:Q16,"✅") | D33: =B33*C33 | E33: =IFERROR(D33/C13,0)
A34: TOTAL XP EARNED | D34: =SUM(D22:D33)
A36: 30-Day XP Log (update daily)
A37: Date | B37: XP Earned | C37: Habits Done | D37: Running Total
A38: 22 Feb 2026 | B38: 132 | C38: 7 | D38: =B38
A39: 23 Feb 2026 | B39: 151 | C39: 11 | D39: =SUM(B38:B39)
A40: 24 Feb 2026 | B40: 62 | C40: 6 | D40: =SUM(B38:B40)
A41: 25 Feb 2026 | B41: 187 | C41: 6 | D41: =SUM(B38:B41)
A42: 26 Feb 2026 | B42: 143 | C42: 10 | D42: =SUM(B38:B42)
A43: 27 Feb 2026 | B43: 64 | C43: 10 | D43: =SUM(B38:B43)
A44: 28 Feb 2026 | B44: 104 | C44: 6 | D44: =SUM(B38:B44)
...

Sheet Heatmap
A1: 🗓 Completion Heatmap — 2026
A2: One cell per day. Purple intensity = XP earned. Your momentum visualised.
B4: Jan | F4: Feb | J4: Mar | N4: Apr | S4: May | W4: Jun | AA4: Jul | AF4: Aug | AJ4: Sep | AO4: Oct | AS4: Nov | AW4: Dec
A5: M | B5: 52 | C5: 119 | D5: 46 | E5: 134 | F5: 18 | G5: 38 | H5: 142 | I5: 89 | J5: 215 | K5: 15 | L5: 210
A6: T | B6: 127 | C6: 149 | D6: 178 | E6: 126 | F6: 30 | G6: 125 | H6: 146 | I6: 152 | J6: 23 | K6: 187 | L6: 114
A7: W | B7: 174 | C7: 116 | D7: 199 | E7: 87 | F7: 131 | G7: 107 | H7: 202 | I7: 127 | J7: 69 | K7: 179 | L7: 72
A8: T | B8: 16 | C8: 136 | D8: 92 | E8: 62 | F8: 186 | G8: 107 | H8: 10 | I8: 209 | J8: 148 | K8: 121 | L8: 79 | M8: 183
A9: F | B9: 144 | C9: 109 | D9: 76 | E9: 20 | F9: 114 | G9: 42 | H9: 171 | I9: 80 | J9: 204 | K9: 178 | L9: 165 | M9: 98
A10: S | B10: 15 | C10: 198 | D10: 63 | E10: 147 | F10: 73 | G10: 193 | H10: 19 | I10: 87 | J10: 116 | K10: 170 | L10: 147 | M10: 171
A11: S | B11: 158 | C11: 80 | D11: 203 | E11: 76 | F11: 155 | G11: 87 | H11: 195 | I11: 177 | J11: 17 | K11: 16 | L11: 174 | M11: 88
A14: Less | B14: None | C14: Low | D14: Mid | E14: High | F14: Max | G14: More

Sheet Analytics
A1: 📈 Analytics & Insights
A2: Track your weekly momentum, XP velocity, and category performance.
A4: 14-Day XP Trend
A5: Date | B5: XP Earned | C5: Done | D5: Rate | I5: 7-Day XP Avg
A6: 10 Mar | B6: 65 | C6: 9 | D6: =IFERROR(C6/12,0) | I6: =AVERAGE(B6:B6)
A7: 11 Mar | B7: 150 | C7: 7 | D7: =IFERROR(C7/12,0) | I7: =AVERAGE(B6:B7)
A8: 12 Mar | B8: 216 | C8: 6 | D8: =IFERROR(C8/12,0) | I8: =AVERAGE(B6:B8)
A9: 13 Mar | B9: 186 | C9: 6 | D9: =IFERROR(C9/12,0) | I9: =AVERAGE(B6:B9)
A10: 14 Mar | B10: 115 | C10: 12 | D10: =IFERROR(C10/12,0) | I10: =AVERAGE(B6:B10)
A11: 15 Mar | B11: 133 | C11: 7 | D11: =IFERROR(C11/12,0) | I11: =AVERAGE(B6:B11)
A12: 16 Mar | B12: 123 | C12: 9 | D12: =IFERROR(C12/12,0) | I12: =AVERAGE(B6:B12)
A13: 17 Mar | B13: 160 | C13: 12 | D13: =IFERROR(C13/12,0) | I13: =AVERAGE(B7:B13)
A14: 18 Mar | B14: 187 | C14: 6 | D14: =IFERROR(C14/12,0) | I14: =AVERAGE(B8:B14)
A15: 19 Mar | B15: 102 | C15: 9 | D15: =IFERROR(C15/12,0) | I15: =AVERAGE(B9:B15)
A16: 20 Mar | B16: 162 | C16: 10 | D16: =IFERROR(C16/12,0) | I16: =AVERAGE(B10:B16)
A17: 21 Mar | B17: 131 | C17: 7 | D17: =IFERROR(C17/12,0) | I17: =AVERAGE(B11:B17)
A18: 22 Mar | B18: 170 | C18: 12 | D18: =IFERROR(C18/12,0) | I18: =AVERAGE(B12:B18)
A19: 23 Mar | B19: 0 | C19: 0 | D19: =IFERROR(C19/12,0) | I19: =AVERAGE(B13:B19)
A21: Weekly XP Summary (Last 8 Weeks)
A22: Week | B22: Mon | C22: Tue | D22: Wed | E22: Thu | F22: Fri | G22: Sat | H22: Sun | I22: Total XP | J22: Rate
A23: Wk 23 Mar | B23: 220 | C23: 151 | D23: 186 | E23: 171 | F23: 177 | G23: 139 | H23: 118 | I23: =SUM(B23:H23) | J23: =IFERROR(I23/(7*220),0)
A24: Wk 16 Mar | B24: 101 | C24: 125 | D24: 118 | E24: 139 | F24: 139 | G24: 83 | H24: 204 | I24: =SUM(B24:H24) | J24: =IFERROR(I24/(7*220),0)
A25: Wk 09 Mar | B25: 126 | C25: 147 | D25: 152 | E25: 81 | F25: 117 | G25: 187 | H25: 216 | I25: =SUM(B25:H25) | J25: =IFERROR(I25/(7*220),0)
A26: Wk 02 Mar | B26: 174 | C26: 161 | D26: 112 | E26: 211 | F26: 93 | G26: 196 | H26: 180 | I26: =SUM(B26:H26) | J26: =IFERROR(I26/(7*220),0)
A27: Wk 23 Feb | B27: 181 | C27: 182 | D27: 180 | E27: 106 | F27: 203 | G27: 182 | H27: 95 | I27: =SUM(B27:H27) | J27: =IFERROR(I27/(7*220),0)
A28: Wk 16 Feb | B28: 128 | C28: 97 | D28: 133 | E28: 192 | F28: 121 | G28: 108 | H28: 167 | I28: =SUM(B28:H28) | J28: =IFERROR(I28/(7*220),0)
A29: Wk 09 Feb | B29: 93 | C29: 106 | D29: 80 | E29: 118 | F29: 217 | G29: 105 | H29: 173 | I29: =SUM(B29:H29) | J29: =IFERROR(I29/(7*220),0)
A30: Wk 02 Feb | B30: 86 | C30: 98 | D30: 133 | E30: 176 | F30: 118 | G30: 144 | H30: 168 | I30: =SUM(B30:H30) | J30: =IFERROR(I30/(7*220),0)
A31: AVERAGE | B31: =AVERAGE(B23:B30) | C31: =AVERAGE(C23:C30) | D31: =AVERAGE(D23:D30) | E31: =AVERAGE(E23:E30) | F31: =AVERAGE(F23:F30) | G31: =AVERAGE(G23:G30) | H31: =AVERAGE(H23:H30) | I31: =AVERAGE(I23:I30) | J31: =AVERAGE(J23:J30)
L33: By Category
L34: Category | M34: # Habits | N34: XP Earned | O34: % of Total
L35: Fitness | M35: =COUNTIFS('Habits Setup'!C5:C104,L35,'Habits Setup'!H5:H104,"Yes") | N35: 716 | O35: =IFERROR(N35/SUM(N35:N41),0)
L36: Health | M36: =COUNTIFS('Habits Setup'!C5:C104,L36,'Habits Setup'!H5:H104,"Yes") | N36: 472 | O36: =IFERROR(N36/SUM(N35:N41),0)
L37: Mindset | M37: =COUNTIFS('Habits Setup'!C5:C104,L37,'Habits Setup'!H5:H104,"Yes") | N37: 585 | O37: =IFERROR(N37/SUM(N35:N41),0)
L38: Focus | M38: =COUNTIFS('Habits Setup'!C5:C104,L38,'Habits Setup'!H5:H104,"Yes") | N38: 225 | O38: =IFERROR(N38/SUM(N35:N41),0)
L39: Business | M39: =COUNTIFS('Habits Setup'!C5:C104,L39,'Habits Setup'!H5:H104,"Yes") | N39: 218 | O39: =IFERROR(N39/SUM(N35:N41),0)
L40: Social | M40: =COUNTIFS('Habits Setup'!C5:C104,L40,'Habits Setup'!H5:H104,"Yes") | N40: 599 | O40: =IFERROR(N40/SUM(N35:N41),0)
L41: Other | M41: =COUNTIFS('Habits Setup'!C5:C104,L41,'Habits Setup'!H5:H104,"Yes") | N41: 577 | O41: =IFERROR(N41/SUM(N35:N41),0)
